<?xml version='1.0'?>

<robot name="rtab_dumpster" xmlns:xacro="http://www.ros.org/wiki/xacro">

<!-- Configure the Gazebo differential drive controller plugin -->
<xacro:arg name="odometryTopic" default="odom" />
<xacro:arg name="odometryFrame" default="odom" />
<xacro:arg name="robotBaseFrame" default="robot_footprint" />
<xacro:arg name="diff_drive_publishTf" default="true" />
<xacro:arg name="diff_drive_publishOdomTF" default="true" />

<xacro:include filename="$(find rtab_dumpster)/urdf/rtab_dumpster.gazebo" />

<link name="robot_footprint"></link>

<!-- Chassis & caster wheels -->

  <joint name="robot_footprint_joint" type="fixed">
    <origin xyz="0 0 0" rpy="0 0 0" />
    <parent link="robot_footprint"/>
    <child link="chassis" />
  </joint>

  <link name='chassis'>
    <pose>0 0 0.15 0 0 0</pose>

    <inertial>
      <mass value="15.0"/>
      <origin xyz="0.0 0 0" rpy=" 0 0 0"/>
      <inertia
          ixx="0.1" ixy="0" ixz="0"
          iyy="0.1" iyz="0"
          izz="0.1"
      />
    </inertial>

    <collision name='collision'>
      <origin xyz="0.0 0 0" rpy=" 0 0 0"/> 
      <geometry>
        <box size=".6 .4 .1"/>
      </geometry>
    </collision>

    <visual name='chassis_visual'>
      <origin xyz="0.0 0 0" rpy=" 0 0 0"/>
      <geometry>
        <box size=".6 .4 .1"/>
      </geometry>
    </visual>

    <collision name='back_caster_collision'>
      <origin xyz="-0.25 0 -0.1" rpy=" 0 0 0"/>
      <geometry>
        <sphere radius="0.0499"/>
      </geometry>
    </collision>

    <visual name='back_caster_visual'>
      <origin xyz="-0.25 0 -0.1" rpy=" 0 0 0"/>
      <geometry>
        <sphere radius="0.05"/>
      </geometry>
    </visual>

    <collision name='front_caster_collision'>
      <origin xyz="0.25 0 -0.1" rpy=" 0 0 0"/>
      <geometry>
        <sphere radius="0.0499"/>
      </geometry>
    </collision>

    <visual name='front_caster_visual'>
      <origin xyz="0.25 0 -0.1" rpy=" 0 0 0"/>
      <geometry>
        <sphere radius="0.05"/>
      </geometry>
    </visual>

  </link>


<!-- Dump box -->
  
    <joint name="dump_box_joint" type="fixed">
    <origin xyz="-0.025 0.0 0.1" rpy="1.57079 0 1.57079" /> <!-- X:front,back, Y:left,right, Z:up,down-->
    <parent link="chassis"/>
    <child link="dump_box" />
  </joint>
 
  <link name='dump_box'>
    <pose>0 0 0 0 0 0</pose>
 
    <inertial>
      <mass value="0.0"/>
      <origin xyz="0 0 -0.1" rpy=" 0 0 0"/>
      <inertia
          ixx="0.1" ixy="0" ixz="0"
          iyy="0.1" iyz="0"
          izz="0.1"
      />
    </inertial>
 
    <collision name='collision'>
      <origin xyz="0 0 -0.1" rpy=" 0 0 0"/> 
      <geometry>
        <box size=".1 .1 .1"/>
      </geometry>
    </collision>
 
    <visual name='dump_box_visual'>
      <origin xyz="-0.355 -0.05 0.1" rpy=" 0 0 0"/>
        <geometry>
        <mesh filename="package://rtab_dumpster/meshes/dumper_bin.dae" scale="0.006 0.006 0.006"/>
        </geometry>
    </visual>
 </link>
 
<!-- plastic bin -->
  <!--
    <joint name="plastic_bin_joint" type="fixed">
 <origin xyz="0.0 0.0 0.0" rpy="0 0 -1.57079" />
<parent link="chassis"/>
 <child link="plastic_bin"/>
</joint>
  
   <link name="plastic_bin">
   <pose>0 0 0 0 0 0</pose>
      <visual>
     <origin xyz="-0.319 -1.895 -0.285" rpy=" 0 0 0"/>
          <geometry>
            <mesh filename="package://rtab_dumpster/meshes/plastic_bin_bin.stl" scale="0.14 0.14 0.14"/>
          </geometry>
        </visual>
      </link>
-->

<!-- kinect pole -->
  
<joint type="fixed" name="kinect_pole_joint">
<!--    <origin xyz="0.275 0.0 0.1" rpy="0 0 0"/> -->
    <origin xyz="0.225 0.0 0.05" rpy="0 0 0"/>
    <child link="kinect_pole"/>
    <parent link="chassis"/>
  </joint>
 
  <link name='kinect_pole'>
    <pose>0 0 0 0 0 0</pose>
 
    <inertial>
      <mass value="0.2"/>
      <origin xyz="0.0 0 0" rpy=" 0 0 0"/>
      <inertia
          ixx="0.1" ixy="0" ixz="0"
          iyy="0.1" iyz="0"
          izz="0.1"
      />
    </inertial>
 
    <collision name='collision'>
      <origin xyz="0 0.0 0.1" rpy=" 0 0 0"/> 
      <geometry>
        <box size="0.05 0.05 0.2"/>
      </geometry>
    </collision>
 
    <visual name='kinect_pole_visual'>
      <origin xyz="0 0.0 0.1" rpy=" 0 0 0"/>
        <geometry>
        <box size="0.05 0.05 0.2"/>
        </geometry>
    </visual>
 
  </link>
  
<!-- laser pole -->
  
<joint type="fixed" name="laser_pole_joint">
   <!-- <origin xyz="0.225 0.0 0.1" rpy="0 0 0"/> -->
    <origin xyz="0.275 0.0 0.05" rpy="0 0 0"/>
    <child link="laser_pole"/>
    <parent link="chassis"/>
  </joint>
 
  <link name='laser_pole'>
    <pose>0 0 0 0 0 0</pose>
 
    <inertial>
      <mass value="0.2"/>
      <origin xyz="0.0 0 0" rpy=" 0 0 0"/>
      <inertia
          ixx="0.1" ixy="0" ixz="0"
          iyy="0.1" iyz="0"
          izz="0.1"
      />
    </inertial>
 
    <collision name='collision'>
      <origin xyz="0 0.0 0.05" rpy=" 0 0 0"/> 
      <geometry>
        <box size="0.05 0.05 0.1"/>
      </geometry>
    </collision>
 
    <visual name='laser_pole_visual'>
      <origin xyz="0 0 0.05" rpy=" 0 0 0"/>
        <geometry>
        <box size="0.05 0.05 0.1"/>
        </geometry>
    </visual>
 
  </link>

<!-- Wheels -->

<joint type="continuous" name="left_wheel_hinge">
    <origin xyz="0 0.25 0" rpy="0 0 0"/>
    <child link="left_wheel"/>
    <parent link="chassis"/>
    <axis xyz="0 1 0" rpy="0 0 0"/>
    <limit effort="10000" velocity="1000"/>
    <dynamics damping="1.0" friction="1.0"/>
  </joint>

<link name='left_wheel'>
    <pose>0 0 0.15 0 0 0</pose>

    <inertial>
      <mass value="5.0"/>
      <origin xyz="0.0 0 0" rpy=" 0 1.5707 1.5707"/>
      <inertia
          ixx="0.1" ixy="0" ixz="0"
          iyy="0.1" iyz="0"
          izz="0.1"
      />
    </inertial>

    <collision name='left_wheel_collision'>
      <origin xyz="0.0 0 0" rpy=" 0 1.5707 1.5707"/>
      <geometry>
        <cylinder radius="0.15" length="0.05"/>
      </geometry>
    </collision>

    <visual name='left_wheel_visual'>
      <origin xyz="0.0 0 0" rpy=" 0 1.5707 1.5707"/>
      <geometry>
        <cylinder radius="0.15" length="0.05"/>
      </geometry>
    </visual>
  </link>

<joint type="continuous" name="right_wheel_hinge">
    <origin xyz="0 -0.25 0" rpy="0 0 0"/>
    <child link="right_wheel"/>
    <parent link="chassis"/>
    <axis xyz="0 1 0" rpy="0 0 0"/>
    <limit effort="10000" velocity="1000"/>
    <dynamics damping="1.0" friction="1.0"/>
  </joint>

<link name='right_wheel'>
    <pose>0 0 0.15 0 0 0</pose>

    <inertial>
      <mass value="5.0"/>
      <origin xyz="0.0 0 0" rpy=" 0 1.5707 1.5707"/>
      <inertia
          ixx="0.1" ixy="0" ixz="0"
          iyy="0.1" iyz="0"
          izz="0.1"
      />
    </inertial>

    <collision name='right_wheel_collision'>
      <origin xyz="0.0 0 0" rpy=" 0 1.5707 1.5707"/>
      <geometry>
        <cylinder radius="0.15" length="0.05"/>
      </geometry>
    </collision>

    <visual name='right_wheel_visual'>
      <origin xyz="0.0 0 0" rpy=" 0 1.5707 1.5707"/>
      <geometry>
        <cylinder radius="0.15" length="0.05"/>
      </geometry>
    </visual>
  </link>

<!-- Camera -->
<!-- link name must match the name of the reference in the .gazebo file -->
<!--
<link name="camera"> 
    <pose>0 0 0.1 0 0 0</pose>

    <inertial>
      <mass value="0.1"/>
      <origin xyz="0.0 0 0" rpy="0 0 0"/>
      <inertia
          ixx="0.0001" ixy="0" ixz="0"
          iyy="0.0001" iyz="0"
          izz="0.0001"
      />
    </inertial>

    <collision name='camera_collision'>
      <origin xyz="0.0 0 0" rpy="0 0 0"/>
      <geometry>
        <box size="0.05 0.05 0.05"/>
      </geometry>
    </collision>

    <visual name='camera_visual'>
      <origin xyz="0.0 0 0" rpy="0 0 0"/>
      <geometry>
         <box size="0.025 0.05 0.05"/>
      </geometry>
    </visual>
  </link>

<joint type="fixed" name="camera_joint">
    <origin xyz="0.0375 0 0.224" rpy="0 0 0"/>
    <child link="camera"/>
    <parent link="laser_pole"/>
  </joint>
-->

<!-- Kinect Sensor -->
<xacro:include filename="$(find rtab_dumpster)/urdf/kinect.xacro"/>

<!-- Laser -->
<link name="hokuyo">
    <pose>0 0 0 0 0 0</pose>

    <inertial>
      <mass value="0.1"/>
      <origin xyz="0.0 0 0" rpy="0 0 0"/>
      <inertia
          ixx="0.0001" ixy="0" ixz="0"
          iyy="0.0001" iyz="0"
          izz="0.0001"
      />
    </inertial>

    <collision name='hokuyo_collision'>
      <origin xyz="0.0 0 0" rpy="0 0 0"/>
      <geometry>
        <box size="0.1 0.1 0.1"/>
      </geometry>
    </collision>

    <visual name='hokuyo_visual'>
      <origin xyz="0.0 0 0" rpy="0 0 0"/>
      <geometry>
         <mesh filename="package://rtab_dumpster/meshes/hokuyo.dae"/>
      </geometry>
    </visual>
  </link>

<joint type="fixed" name="hokuyo_joint">
    <origin xyz="0.0 0 0.135" rpy="0 0 0"/> <!-- set height relative to laser_pole -->
    <child link="hokuyo"/>
    <parent link="laser_pole"/>
  </joint>

</robot>
